Workbook

Sheet Read_Me
A1: Auditable Flourishing v6.2 External Pilot Aggregation Workbook
A3: Field | B3: Binding instruction
A4: Protocol status | B4: Master specification frozen; publication-integrity and provenance closure complete; Phase 0 design-ready; materials, host, reviewer pool, external reliability, validity, burden, fairness, legitimacy and decision-value evidence remain open.
A5: Purpose | B5: Prospective aggregation after source records are captured in independently controlled, timestamped and hash-bound systems.
A6: Not authorized | B6: This workbook is not an immutable deposit system, certification instrument, legal opinion, flourishing measure, due-diligence safe harbor, foreseeability finding or deployment authorization.
A7: Positive Stage A label | B7: Use exact bounded status, canonical token, candidate, scope, evidence cut-off, protocol version, CL basis, host, conditions, expiry, dissent and appeal route.
A8: Non-compensation | B8: A material C0-C5 defect cannot be offset by strength elsewhere.
A9: Burden gate | B9: Feasibility is conjunctive across numeric validity, reviewer and adjudication hours, calendar, reviewer count, access, translation, custody and governance.
A10: Independence | B10: Unknown control values route to Indeterminate; recognized capture, missing reporting protection, undisclosed model rating or publication veto routes to Inadequate.
A11: Public claims | B11: Never export bare Pass, Approved, Certified, Safe, Ethical, Legitimate, Compliant, Due-Diligence, Foreseeable/Unforeseeable or Authorized labels.
A12: Evidence | B12: Documentary and non-documentary evidence requires provenance, consent, custody, translation, challengeability, compensation, sovereignty and withdrawal conditions.
A13: Reliability | B13: Raw agreement is descriptive. Versioned external scripts compute AC1/AC2, alpha, intervals, exclusions and sensitivity analyses; negative adverse results are permitted.
A14: Configured data capacity
A15: Workbook sequence
A16: 1 | B16: Vocabulary - controlling lists, protocol version and constitutional-legitimacy basis.
A17: 2 | B17: Profile_Routing - incomplete or unrecognized routes remain undetermined; no downward default.
A18: 3 | B18: Candidate_Register - bind candidate, version, scope, authority claim, access and evidence cut-off.
A19: 4 | B19: Study_Readiness - distinguish design-ready, materials-ready, shadow-ready, pilot-ready and replication-ready.
A20: 5 | B20: Scenario_Register - bind frozen scenario-set version, equivalence criteria, calibration, access and hash.
A21: 6 | B21: Stage_A - six recognized criterion states are required. Refusal prerequisites route first; established unpatchable defects control over patchable defects; established patchable defects control over unresolved criterion evidence; only then can indeterminate or admissible outcomes be assigned.
A22: 7 | B22: Stage_A - only six recognized adequate/control-dependent findings can support admissibility; administrative statuses have an explicit derived route.
A23: 8 | B23: Verdict_Vector - separate AF eligibility from legal, moral, community and deployment findings.
A24: 9 | B24: Independence - use positive whitelists, protected reporting and anti-retaliation controls.
A25: 10 | B25: Perturbation_Register - proposals require evidence and independent admission before replay.
A26: 11 | B26: Burden_Log - test access, translation, custody, governance and capacity conjunctively.
A27: 12 | B27: Decision_Value - retain positive, null and adverse results.
... A31: Canonical registry | B31: The Core Protocol controls. release/AF_CANONICAL_REGISTRY_v6_2.json binds release version, stable component IDs, Stage A precedence, AF-SB12, and artifact authority; the workbook cannot override it.

Sheet Profile_Routing
A1: AF v6.2 Profile Routing
A3: Routing_ID | B3: Candidate_ID | C3: Declared_Scope | D3: Stakes | E3: Rights_Impact | F3: Irreversibility | G3: Population_Scale | H3: Novelty | I3: Contestation | J3: Candidate_Capacity | K3: Review_Capacity | L3: Access_Support | M3: Derived_Profile | N3: Recorded_Profile | O3: Routing_Match | P3: Rationale | Q3: Vocabulary_Check
A4: ROUTE-ILL-001 | B4: SYNTH-CAND-HC | C4: National benefits eligibility architecture | D4: High | E4: Fundamental or uncertain | F4: Difficult to reverse | G4: National/transnational/ecological | H4: Novel | I4: Affected-party dispute or unknown | J4: Constrained | K4: Adequate | L4: Yes | M4: =IF(COUNTA(A4:L4)=0,"",IF(OR(LEN(TRIM(B4))=0,LEN(TRIM(C4))=0,LEN(TRIM(D4))=0,LEN(TRIM(E4))=0,LEN(TRIM(F4))=0,LEN(TRIM(G4))=0,LEN(TRIM(H4))=0,LEN(TRIM(I4))=0,LEN(TRIM(J4))=0,LEN(TRIM(K4))=0,LEN(TRIM(L4))=0),"Undetermined - incomplete routing",IF(Q4<>"OK","Undetermined - unrecognized routing value",IF(OR(D4="High",D4="Catastrophic/systemic",E4="Material",E4="Fundamental or uncertain",F4="Difficult to reverse",F4="Irreversible or unknown",G4="National/transnational/ecological",H4="Frontier or unknown",I4="Affected-party dispute or unknown"),"AF-High-Consequence",IF(OR(D4="Moderate",E4="Limited reversible",F4="Partly reversible",G4="Regional/sectoral",H4="Novel",I4="High"),"AF-Standard","AF-Lite"))))) | N4: AF-High-Consequence | O4: =IF(AND(M4="",N4=""),"",IF(AND(M4<>"",N4=""),"UNRECORDED",IF(AND(M4="",N4<>""),"ORPHAN_RECORDED",IF(M4=N4,"MATCH","MISMATCH")))) | P4: Illustrative high-consequence route; constrained resources trigger support, not a lower standard. | Q4: =IF(COUNTA(A4:L4)=0,"",IF(AND(COUNTIF(Vocabulary!$C$5:$C$8,D4)=1,COUNTIF(Vocabulary!$D$5:$D$8,E4)=1,COUNTIF(Vocabulary!$E$5:$E$8,F4)=1,COUNTIF(Vocabulary!$F$5:$F$8,G4)=1,COUNTIF(Vocabulary!$G$5:$G$8,H4)=1,COUNTIF(Vocabulary!$H$5:$H$8,I4)=1,COUNTIF(Vocabulary!$I$5:$I$7,J4)=1,COUNTIF(Vocabulary!$I$5:$I$7,K4)=1,COUNTIF(Vocabulary!$J$5:$J$6,L4)=1),"OK","UNRECOGNISED_ROUTING_VALUE"))
A5: ROUTE-ILL-002 | B5: SYNTH-CAND-LITE | C5: Local reversible advisory workshop | D5: Low | E5: None identified | F5: Reversible | G5: Local/small | H5: Routine | I5: Low | J5: Adequate | K5: Adequate | L5: No | M5: =IF(COUNTA(A5:L5)=0,"",IF(OR(LEN(TRIM(B5))=0,LEN(TRIM(C5))=0,LEN(TRIM(D5))=0,LEN(TRIM(E5))=0,LEN(TRIM(F5))=0,LEN(TRIM(G5))=0,LEN(TRIM(H5))=0,LEN(TRIM(I5))=0,LEN(TRIM(J5))=0,LEN(TRIM(K5))=0,LEN(TRIM(L5))=0),"Undetermined - incomplete routing",IF(Q5<>"OK","Undetermined - unrecognized routing value",IF(OR(D5="High",D5="Catastrophic/systemic",E5="Material",E5="Fundamental or uncertain",F5="Difficult to reverse",F5="Irreversible or unknown",G5="National/transnational/ecological",H5="Frontier or unknown",I5="Affected-party dispute or unknown"),"AF-High-Consequence",IF(OR(D5="Moderate",E5="Limited reversible",F5="Partly reversible",G5="Regional/sectoral",H5="Novel",I5="High"),"AF-Standard","AF-Lite"))))) | N5: AF-Lite | O5: =IF(AND(M5="",N5=""),"",IF(AND(M5<>"",N5=""),"UNRECORDED",IF(AND(M5="",N5<>""),"ORPHAN_RECORDED",IF(M5=N5,"MATCH","MISMATCH")))) | P5: Illustrative low-stakes route. | Q5: =IF(COUNTA(A5:L5)=0,"",IF(AND(COUNTIF(Vocabulary!$C$5:$C$8,D5)=1,COUNTIF(Vocabulary!$D$5:$D$8,E5)=1,COUNTIF(Vocabulary!$E$5:$E$8,F5)=1,COUNTIF(Vocabulary!$F$5:$F$8,G5)=1,COUNTIF(Vocabulary!$G$5:$G$8,H5)=1,COUNTIF(Vocabulary!$H$5:$H$8,I5)=1,COUNTIF(Vocabulary!$I$5:$I$7,J5)=1,COUNTIF(Vocabulary!$I$5:$I$7,K5)=1,COUNTIF(Vocabulary!$J$5:$J$6,L5)=1),"OK","UNRECOGNISED_ROUTING_VALUE"))
M6: =IF(COUNTA(A6:L6)=0,"",IF(OR(LEN(TRIM(B6))=0,LEN(TRIM(C6))=0,LEN(TRIM(D6))=0,LEN(TRIM(E6))=0,LEN(TRIM(F6))=0,LEN(TRIM(G6))=0,LEN(TRIM(H6))=0,LEN(TRIM(I6))=0,LEN(TRIM(J6))=0,LEN(TRIM(K6))=0,LEN(TRIM(L6))=0),"Undetermined - incomplete routing",IF(Q6<>"OK","Undetermined - unrecognized routing value",IF(OR(D6="High",D6="Catastrophic/systemic",E6="Material",E6="Fundamental or uncertain",F6="Difficult to reverse",F6="Irreversible or unknown",G6="National/transnational/ecological",H6="Frontier or unknown",I6="Affected-party dispute or unknown"),"AF-High-Consequence",IF(OR(D6="Moderate",E6="Limited reversible",F6="Partly reversible",G6="Regional/sectoral",H6="Novel",I6="High"),"AF-Standard","AF-Lite"))))) | O6: =IF(AND(M6="",N6=""),"",IF(AND(M6<>"",N6=""),"UNRECORDED",IF(AND(M6="",N6<>""),"ORPHAN_RECORDED",IF(M6=N6,"MATCH","MISMATCH")))) | Q6: =IF(COUNTA(A6:L6)=0,"",IF(AND(COUNTIF(Vocabulary!$C$5:$C$8,D6)=1,COUNTIF(Vocabulary!$D$5:$D$8,E6)=1,COUNTIF(Vocabulary!$E$5:$E$8,F6)=1,COUNTIF(Vocabulary!$F$5:$F$8,G6)=1,COUNTIF(Vocabulary!$G$5:$G$8,H6)=1,COUNTIF(Vocabulary!$H$5:$H$8,I6)=1,COUNTIF(Vocabulary!$I$5:$I$7,J6)=1,COUNTIF(Vocabulary!$I$5:$I$7,K6)=1,COUNTIF(Vocabulary!$J$5:$J$6,L6)=1),"OK","UNRECOGNISED_ROUTING_VALUE"))
M7: =IF(COUNTA(A7:L7)=0,"",IF(OR(LEN(TRIM(B7))=0,LEN(TRIM(C7))=0,LEN(TRIM(D7))=0,LEN(TRIM(E7))=0,LEN(TRIM(F7))=0,LEN(TRIM(G7))=0,LEN(TRIM(H7))=0,LEN(TRIM(I7))=0,LEN(TRIM(J7))=0,LEN(TRIM(K7))=0,LEN(TRIM(L7))=0),"Undetermined - incomplete routing",IF(Q7<>"OK","Undetermined - unrecognized routing value",IF(OR(D7="High",D7="Catastrophic/systemic",E7="Material",E7="Fundamental or uncertain",F7="Difficult to reverse",F7="Irreversible or unknown",G7="National/transnational/ecological",H7="Frontier or unknown",I7="Affected-party dispute or unknown"),"AF-High-Consequence",IF(OR(D7="Moderate",E7="Limited reversible",F7="Partly reversible",G7="Regional/sectoral",H7="Novel",I7="High"),"AF-Standard","AF-Lite"))))) | O7: =IF(AND(M7="",N7=""),"",IF(AND(M7<>"",N7=""),"UNRECORDED",IF(AND(M7="",N7<>""),"ORPHAN_RECORDED",IF(M7=N7,"MATCH","MISMATCH")))) | Q7: =IF(COUNTA(A7:L7)=0,"",IF(AND(COUNTIF(Vocabulary!$C$5:$C$8,D7)=1,COUNTIF(Vocabulary!$D$5:$D$8,E7)=1,COUNTIF(Vocabulary!$E$5:$E$8,F7)=1,COUNTIF(Vocabulary!$F$5:$F$8,G7)=1,COUNTIF(Vocabulary!$G$5:$G$8,H7)=1,COUNTIF(Vocabulary!$H$5:$H$8,I7)=1,COUNTIF(Vocabulary!$I$5:$I$7,J7)=1,COUNTIF(Vocabulary!$I$5:$I$7,K7)=1,COUNTIF(Vocabulary!$J$5:$J$6,L7)=1),"OK","UNRECOGNISED_ROUTING_VALUE"))
M8: =IF(COUNTA(A8:L8)=0,"",IF(OR(LEN(TRIM(B8))=0,LEN(TRIM(C8))=0,LEN(TRIM(D8))=0,LEN(TRIM(E8))=0,LEN(TRIM(F8))=0,LEN(TRIM(G8))=0,LEN(TRIM(H8))=0,LEN(TRIM(I8))=0,LEN(TRIM(J8))=0,LEN(TRIM(K8))=0,LEN(TRIM(L8))=0),"Undetermined - incomplete routing",IF(Q8<>"OK","Undetermined - unrecognized routing value",IF(OR(D8="High",D8="Catastrophic/systemic",E8="Material",E8="Fundamental or uncertain",F8="Difficult to reverse",F8="Irreversible or unknown",G8="National/transnational/ecological",H8="Frontier or unknown",I8="Affected-party dispute or unknown"),"AF-High-Consequence",IF(OR(D8="Moderate",E8="Limited reversible",F8="Partly reversible",G8="Regional/sectoral",H8="Novel",I8="High"),"AF-Standard","AF-Lite"))))) | O8: =IF(AND(M8="",N8=""),"",IF(AND(M8<>"",N8=""),"UNRECORDED",IF(AND(M8="",N8<>""),"ORPHAN_RECORDED",IF(M8=N8,"MATCH","MISMATCH")))) | Q8: =IF(COUNTA(A8:L8)=0,"",IF(AND(COUNTIF(Vocabulary!$C$5:$C$8,D8)=1,COUNTIF(Vocabulary!$D$5:$D$8,E8)=1,COUNTIF(Vocabulary!$E$5:$E$8,F8)=1,COUNTIF(Vocabulary!$F$5:$F$8,G8)=1,COUNTIF(Vocabulary!$G$5:$G$8,H8)=1,COUNTIF(Vocabulary!$H$5:$H$8,I8)=1,COUNTIF(Vocabulary!$I$5:$I$7,J8)=1,COUNTIF(Vocabulary!$I$5:$I$7,K8)=1,COUNTIF(Vocabulary!$J$5:$J$6,L8)=1),"OK","UNRECOGNISED_ROUTING_VALUE"))
M9: =IF(COUNTA(A9:L9)=0,"",IF(OR(LEN(TRIM(B9))=0,LEN(TRIM(C9))=0,LEN(TRIM(D9))=0,LEN(TRIM(E9))=0,LEN(TRIM(F9))=0,LEN(TRIM(G9))=0,LEN(TRIM(H9))=0,LEN(TRIM(I9))=0,LEN(TRIM(J9))=0,LEN(TRIM(K9))=0,LEN(TRIM(L9))=0),"Undetermined - incomplete routing",IF(Q9<>"OK","Undetermined - unrecognized routing value",IF(OR(D9="High",D9="Catastrophic/systemic",E9="Material",E9="Fundamental or uncertain",F9="Difficult to reverse",F9="Irreversible or unknown",G9="National/transnational/ecological",H9="Frontier or unknown",I9="Affected-party dispute or unknown"),"AF-High-Consequence",IF(OR(D9="Moderate",E9="Limited reversible",F9="Partly reversible",G9="Regional/sectoral",H9="Novel",I9="High"),"AF-Standard","AF-Lite"))))) | O9: =IF(AND(M9="",N9=""),"",IF(AND(M9<>"",N9=""),"UNRECORDED",IF(AND(M9="",N9<>""),"ORPHAN_RECORDED",IF(M9=N9,"MATCH","MISMATCH")))) | Q9: =IF(COUNTA(A9:L9)=0,"",IF(AND(COUNTIF(Vocabulary!$C$5:$C$8,D9)=1,COUNTIF(Vocabulary!$D$5:$D$8,E9)=1,COUNTIF(Vocabulary!$E$5:$E$8,F9)=1,COUNTIF(Vocabulary!$F$5:$F$8,G9)=1,COUNTIF(Vocabulary!$G$5:$G$8,H9)=1,COUNTIF(Vocabulary!$H$5:$H$8,I9)=1,COUNTIF(Vocabulary!$I$5:$I$7,J9)=1,COUNTIF(Vocabulary!$I$5:$I$7,K9)=1,COUNTIF(Vocabulary!$J$5:$J$6,L9)=1),"OK","UNRECOGNISED_ROUTING_VALUE"))
M10: =IF(COUNTA(A10:L10)=0,"",IF(OR(LEN(TRIM(B10))=0,LEN(TRIM(C10))=0,LEN(TRIM(D10))=0,LEN(TRIM(E10))=0,LEN(TRIM(F10))=0,LEN(TRIM(G10))=0,LEN(TRIM(H10))=0,LEN(TRIM(I10))=0,LEN(TRIM(J10))=0,LEN(TRIM(K10))=0,LEN(TRIM(L10))=0),"Undetermined - incomplete routing",IF(Q10<>"OK","Undetermined - unrecognized routing value",IF(OR(D10="High",D10="Catastrophic/systemic",E10="Material",E10="Fundamental or uncertain",F10="Difficult to reverse",F10="Irreversible or unknown",G10="National/transnational/ecological",H10="Frontier or unknown",I10="Affected-party dispute or unknown"),"AF-High-Consequence",IF(OR(D10="Moderate",E10="Limited reversible",F10="Partly reversible",G10="Regional/sectoral",H10="Novel",I10="High"),"AF-Standard","AF-Lite"))))) | O10: =IF(AND(M10="",N10=""),"",IF(AND(M10<>"",N10=""),"UNRECORDED",IF(AND(M10="",N10<>""),"ORPHAN_RECORDED",IF(M10=N10,"MATCH","MISMATCH")))) | Q10: =IF(COUNTA(A10:L10)=0,"",IF(AND(COUNTIF(Vocabulary!$C$5:$C$8,D10)=1,COUNTIF(Vocabulary!$D$5:$D$8,E10)=1,COUNTIF(Vocabulary!$E$5:$E$8,F10)=1,COUNTIF(Vocabulary!$F$5:$F$8,G10)=1,COUNTIF(Vocabulary!$G$5:$G$8,H10)=1,COUNTIF(Vocabulary!$H$5:$H$8,I10)=1,COUNTIF(Vocabulary!$I$5:$I$7,J10)=1,COUNTIF(Vocabulary!$I$5:$I$7,K10)=1,COUNTIF(Vocabulary!$J$5:$J$6,L10)=1),"OK","UNRECOGNISED_ROUTING_VALUE"))
M11: =IF(COUNTA(A11:L11)=0,"",IF(OR(LEN(TRIM(B11))=0,LEN(TRIM(C11))=0,LEN(TRIM(D11))=0,LEN(TRIM(E11))=0,LEN(TRIM(F11))=0,LEN(TRIM(G11))=0,LEN(TRIM(H11))=0,LEN(TRIM(I11))=0,LEN(TRIM(J11))=0,LEN(TRIM(K11))=0,LEN(TRIM(L11))=0),"Undetermined - incomplete routing",IF(Q11<>"OK","Undetermined - unrecognized routing value",IF(OR(D11="High",D11="Catastrophic/systemic",E11="Material",E11="Fundamental or uncertain",F11="Difficult to reverse",F11="Irreversible or unknown",G11="National/transnational/ecological",H11="Frontier or unknown",I11="Affected-party dispute or unknown"),"AF-High-Consequence",IF(OR(D11="Moderate",E11="Limited reversible",F11="Partly reversible",G11="Regional/sectoral",H11="Novel",I11="High"),"AF-Standard","AF-Lite"))))) | O11: =IF(AND(M11="",N11=""),"",IF(AND(M11<>"",N11=""),"UNRECORDED",IF(AND(M11="",N11<>""),"ORPHAN_RECORDED",IF(M11=N11,"MATCH","MISMATCH")))) | Q11: =IF(COUNTA(A11:L11)=0,"",IF(AND(COUNTIF(Vocabulary!$C$5:$C$8,D11)=1,COUNTIF(Vocabulary!$D$5:$D$8,E11)=1,COUNTIF(Vocabulary!$E$5:$E$8,F11)=1,COUNTIF(Vocabulary!$F$5:$F$8,G11)=1,COUNTIF(Vocabulary!$G$5:$G$8,H11)=1,COUNTIF(Vocabulary!$H$5:$H$8,I11)=1,COUNTIF(Vocabulary!$I$5:$I$7,J11)=1,COUNTIF(Vocabulary!$I$5:$I$7,K11)=1,COUNTIF(Vocabulary!$J$5:$J$6,L11)=1),"OK","UNRECOGNISED_ROUTING_VALUE"))
M12: =IF(COUNTA(A12:L12)=0,"",IF(OR(LEN(TRIM(B12))=0,LEN(TRIM(C12))=0,LEN(TRIM(D12))=0,LEN(TRIM(E12))=0,LEN(TRIM(F12))=0,LEN(TRIM(G12))=0,LEN(TRIM(H12))=0,LEN(TRIM(I12))=0,LEN(TRIM(J12))=0,LEN(TRIM(K12))=0,LEN(TRIM(L12))=0),"Undetermined - incomplete routing",IF(Q12<>"OK","Undetermined - unrecognized routing value",IF(OR(D12="High",D12="Catastrophic/systemic",E12="Material",E12="Fundamental or uncertain",F12="Difficult to reverse",F12="Irreversible or unknown",G12="National/transnational/ecological",H12="Frontier or unknown",I12="Affected-party dispute or unknown"),"AF-High-Consequence",IF(OR(D12="Moderate",E12="Limited reversible",F12="Partly reversible",G12="Regional/sectoral",H12="Novel",I12="High"),"AF-Standard","AF-Lite"))))) | O12: =IF(AND(M12="",N12=""),"",IF(AND(M12<>"",N12=""),"UNRECORDED",IF(AND(M12="",N12<>""),"ORPHAN_RECORDED",IF(M12=N12,"MATCH","MISMATCH")))) | Q12: =IF(COUNTA(A12:L12)=0,"",IF(AND(COUNTIF(Vocabulary!$C$5:$C$8,D12)=1,COUNTIF(Vocabulary!$D$5:$D$8,E12)=1,COUNTIF(Vocabulary!$E$5:$E$8,F12)=1,COUNTIF(Vocabulary!$F$5:$F$8,G12)=1,COUNTIF(Vocabulary!$G$5:$G$8,H12)=1,COUNTIF(Vocabulary!$H$5:$H$8,I12)=1,COUNTIF(Vocabulary!$I$5:$I$7,J12)=1,COUNTIF(Vocabulary!$I$5:$I$7,K12)=1,COUNTIF(Vocabulary!$J$5:$J$6,L12)=1),"OK","UNRECOGNISED_ROUTING_VALUE"))
M13: =IF(COUNTA(A13:L13)=0,"",IF(OR(LEN(TRIM(B13))=0,LEN(TRIM(C13))=0,LEN(TRIM(D13))=0,LEN(TRIM(E13))=0,LEN(TRIM(F13))=0,LEN(TRIM(G13))=0,LEN(TRIM(H13))=0,LEN(TRIM(I13))=0,LEN(TRIM(J13))=0,LEN(TRIM(K13))=0,LEN(TRIM(L13))=0),"Undetermined - incomplete routing",IF(Q13<>"OK","Undetermined - unrecognized routing value",IF(OR(D13="High",D13="Catastrophic/systemic",E13="Material",E13="Fundamental or uncertain",F13="Difficult to reverse",F13="Irreversible or unknown",G13="National/transnational/ecological",H13="Frontier or unknown",I13="Affected-party dispute or unknown"),"AF-High-Consequence",IF(OR(D13="Moderate",E13="Limited reversible",F13="Partly reversible",G13="Regional/sectoral",H13="Novel",I13="High"),"AF-Standard","AF-Lite"))))) | O13: =IF(AND(M13="",N13=""),"",IF(AND(M13<>"",N13=""),"UNRECORDED",IF(AND(M13="",N13<>""),"ORPHAN_RECORDED",IF(M13=N13,"MATCH","MISMATCH")))) | Q13: =IF(COUNTA(A13:L13)=0,"",IF(AND(COUNTIF(Vocabulary!$C$5:$C$8,D13)=1,COUNTIF(Vocabulary!$D$5:$D$8,E13)=1,COUNTIF(Vocabulary!$E$5:$E$8,F13)=1,COUNTIF(Vocabulary!$F$5:$F$8,G13)=1,COUNTIF(Vocabulary!$G$5:$G$8,H13)=1,COUNTIF(Vocabulary!$H$5:$H$8,I13)=1,COUNTIF(Vocabulary!$I$5:$I$7,J13)=1,COUNTIF(Vocabulary!$I$5:$I$7,K13)=1,COUNTIF(Vocabulary!$J$5:$J$6,L13)=1),"OK","UNRECOGNISED_ROUTING_VALUE"))
M14: =IF(COUNTA(A14:L14)=0,"",IF(OR(LEN(TRIM(B14))=0,LEN(TRIM(C14))=0,LEN(TRIM(D14))=0,LEN(TRIM(E14))=0,LEN(TRIM(F14))=0,LEN(TRIM(G14))=0,LEN(TRIM(H14))=0,LEN(TRIM(I14))=0,LEN(TRIM(J14))=0,LEN(TRIM(K14))=0,LEN(TRIM(L14))=0),"Undetermined - incomplete routing",IF(Q14<>"OK","Undetermined - unrecognized routing value",IF(OR(D14="High",D14="Catastrophic/systemic",E14="Material",E14="Fundamental or uncertain",F14="Difficult to reverse",F14="Irreversible or unknown",G14="National/transnational/ecological",H14="Frontier or unknown",I14="Affected-party dispute or unknown"),"AF-High-Consequence",IF(OR(D14="Moderate",E14="Limited reversible",F14="Partly reversible",G14="Regional/sectoral",H14="Novel",I14="High"),"AF-Standard","AF-Lite"))))) | O14: =IF(AND(M14="",N14=""),"",IF(AND(M14<>"",N14=""),"UNRECORDED",IF(AND(M14="",N14<>""),"ORPHAN_RECORDED",IF(M14=N14,"MATCH","MISMATCH")))) | Q14: =IF(COUNTA(A14:L14)=0,"",IF(AND(COUNTIF(Vocabulary!$C$5:$C$8,D14)=1,COUNTIF(Vocabulary!$D$5:$D$8,E14)=1,COUNTIF(Vocabulary!$E$5:$E$8,F14)=1,COUNTIF(Vocabulary!$F$5:$F$8,G14)=1,COUNTIF(Vocabulary!$G$5:$G$8,H14)=1,COUNTIF(Vocabulary!$H$5:$H$8,I14)=1,COUNTIF(Vocabulary!$I$5:$I$7,J14)=1,COUNTIF(Vocabulary!$I$5:$I$7,K14)=1,COUNTIF(Vocabulary!$J$5:$J$6,L14)=1),"OK","UNRECOGNISED_ROUTING_VALUE"))
M15: =IF(COUNTA(A15:L15)=0,"",IF(OR(LEN(TRIM(B15))=0,LEN(TRIM(C15))=0,LEN(TRIM(D15))=0,LEN(TRIM(E15))=0,LEN(TRIM(F15))=0,LEN(TRIM(G15))=0,LEN(TRIM(H15))=0,LEN(TRIM(I15))=0,LEN(TRIM(J15))=0,LEN(TRIM(K15))=0,LEN(TRIM(L15))=0),"Undetermined - incomplete routing",IF(Q15<>"OK","Undetermined - unrecognized routing value",IF(OR(D15="High",D15="Catastrophic/systemic",E15="Material",E15="Fundamental or uncertain",F15="Difficult to reverse",F15="Irreversible or unknown",G15="National/transnational/ecological",H15="Frontier or unknown",I15="Affected-party dispute or unknown"),"AF-High-Consequence",IF(OR(D15="Moderate",E15="Limited reversible",F15="Partly reversible",G15="Regional/sectoral",H15="Novel",I15="High"),"AF-Standard","AF-Lite"))))) | O15: =IF(AND(M15="",N15=""),"",IF(AND(M15<>"",N15=""),"UNRECORDED",IF(AND(M15="",N15<>""),"ORPHAN_RECORDED",IF(M15=N15,"MATCH","MISMATCH")))) | Q15: =IF(COUNTA(A15:L15)=0,"",IF(AND(COUNTIF(Vocabulary!$C$5:$C$8,D15)=1,COUNTIF(Vocabulary!$D$5:$D$8,E15)=1,COUNTIF(Vocabulary!$E$5:$E$8,F15)=1,COUNTIF(Vocabulary!$F$5:$F$8,G15)=1,COUNTIF(Vocabulary!$G$5:$G$8,H15)=1,COUNTIF(Vocabulary!$H$5:$H$8,I15)=1,COUNTIF(Vocabulary!$I$5:$I$7,J15)=1,COUNTIF(Vocabulary!$I$5:$I$7,K15)=1,COUNTIF(Vocabulary!$J$5:$J$6,L15)=1),"OK","UNRECOGNISED_ROUTING_VALUE"))
M16: =IF(COUNTA(A16:L16)=0,"",IF(OR(LEN(TRIM(B16))=0,LEN(TRIM(C16))=0,LEN(TRIM(D16))=0,LEN(TRIM(E16))=0,LEN(TRIM(F16))=0,LEN(TRIM(G16))=0,LEN(TRIM(H16))=0,LEN(TRIM(I16))=0,LEN(TRIM(J16))=0,LEN(TRIM(K16))=0,LEN(TRIM(L16))=0),"Undetermined - incomplete routing",IF(Q16<>"OK","Undetermined - unrecognized routing value",IF(OR(D16="High",D16="Catastrophic/systemic",E16="Material",E16="Fundamental or uncertain",F16="Difficult to reverse",F16="Irreversible or unknown",G16="National/transnational/ecological",H16="Frontier or unknown",I16="Affected-party dispute or unknown"),"AF-High-Consequence",IF(OR(D16="Moderate",E16="Limited reversible",F16="Partly reversible",G16="Regional/sectoral",H16="Novel",I16="High"),"AF-Standard","AF-Lite"))))) | O16: =IF(AND(M16="",N16=""),"",IF(AND(M16<>"",N16=""),"UNRECORDED",IF(AND(M16="",N16<>""),"ORPHAN_RECORDED",IF(M16=N16,"MATCH","MISMATCH")))) | Q16: =IF(COUNTA(A16:L16)=0,"",IF(AND(COUNTIF(Vocabulary!$C$5:$C$8,D16)=1,COUNTIF(Vocabulary!$D$5:$D$8,E16)=1,COUNTIF(Vocabulary!$E$5:$E$8,F16)=1,COUNTIF(Vocabulary!$F$5:$F$8,G16)=1,COUNTIF(Vocabulary!$G$5:$G$8,H16)=1,COUNTIF(Vocabulary!$H$5:$H$8,I16)=1,COUNTIF(Vocabulary!$I$5:$I$7,J16)=1,COUNTIF(Vocabulary!$I$5:$I$7,K16)=1,COUNTIF(Vocabulary!$J$5:$J$6,L16)=1),"OK","UNRECOGNISED_ROUTING_VALUE"))
M17: =IF(COUNTA(A17:L17)=0,"",IF(OR(LEN(TRIM(B17))=0,LEN(TRIM(C17))=0,LEN(TRIM(D17))=0,LEN(TRIM(E17))=0,LEN(TRIM(F17))=0,LEN(TRIM(G17))=0,LEN(TRIM(H17))=0,LEN(TRIM(I17))=0,LEN(TRIM(J17))=0,LEN(TRIM(K17))=0,LEN(TRIM(L17))=0),"Undetermined - incomplete routing",IF(Q17<>"OK","Undetermined - unrecognized routing value",IF(OR(D17="High",D17="Catastrophic/systemic",E17="Material",E17="Fundamental or uncertain",F17="Difficult to reverse",F17="Irreversible or unknown",G17="National/transnational/ecological",H17="Frontier or unknown",I17="Affected-party dispute or unknown"),"AF-High-Consequence",IF(OR(D17="Moderate",E17="Limited reversible",F17="Partly reversible",G17="Regional/sectoral",H17="Novel",I17="High"),"AF-Standard","AF-Lite"))))) | O17: =IF(AND(M17="",N17=""),"",IF(AND(M17<>"",N17=""),"UNRECORDED",IF(AND(M17="",N17<>""),"ORPHAN_RECORDED",IF(M17=N17,"MATCH","MISMATCH")))) | Q17: =IF(COUNTA(A17:L17)=0,"",IF(AND(COUNTIF(Vocabulary!$C$5:$C$8,D17)=1,COUNTIF(Vocabulary!$D$5:$D$8,E17)=1,COUNTIF(Vocabulary!$E$5:$E$8,F17)=1,COUNTIF(Vocabulary!$F$5:$F$8,G17)=1,COUNTIF(Vocabulary!$G$5:$G$8,H17)=1,COUNTIF(Vocabulary!$H$5:$H$8,I17)=1,COUNTIF(Vocabulary!$I$5:$I$7,J17)=1,COUNTIF(Vocabulary!$I$5:$I$7,K17)=1,COUNTIF(Vocabulary!$J$5:$J$6,L17)=1),"OK","UNRECOGNISED_ROUTING_VALUE"))
... M250: =IF(COUNTA(A250:L250)=0,"",IF(OR(LEN(TRIM(B250))=0,LEN(TRIM(C250))=0,LEN(TRIM(D250))=0,LEN(TRIM(E250))=0,LEN(TRIM(F250))=0,LEN(TRIM(G250))=0,LEN(TRIM(H250))=0,LEN(TRIM(I250))=0,LEN(TRIM(J250))=0,LEN(TRIM(K250))=0,LEN(TRIM(L250))=0),"Undetermined - incomplete routing",IF(Q250<>"OK","Undetermined - unrecognized routing value",IF(OR(D250="High",D250="Catastrophic/systemic",E250="Material",E250="Fundamental or uncertain",F250="Difficult to reverse",F250="Irreversible or unknown",G250="National/transnational/ecological",H250="Frontier or unknown",I250="Affected-party dispute or unknown"),"AF-High-Consequence",IF(OR(D250="Moderate",E250="Limited reversible",F250="Partly reversible",G250="Regional/sectoral",H250="Novel",I250="High"),"AF-Standard","AF-Lite"))))) | O250: =IF(AND(M250="",N250=""),"",IF(AND(M250<>"",N250=""),"UNRECORDED",IF(AND(M250="",N250<>""),"ORPHAN_RECORDED",IF(M250=N250,"MATCH","MISMATCH")))) | Q250: =IF(COUNTA(A250:L250)=0,"",IF(AND(COUNTIF(Vocabulary!$C$5:$C$8,D250)=1,COUNTIF(Vocabulary!$D$5:$D$8,E250)=1,COUNTIF(Vocabulary!$E$5:$E$8,F250)=1,COUNTIF(Vocabulary!$F$5:$F$8,G250)=1,COUNTIF(Vocabulary!$G$5:$G$8,H250)=1,COUNTIF(Vocabulary!$H$5:$H$8,I250)=1,COUNTIF(Vocabulary!$I$5:$I$7,J250)=1,COUNTIF(Vocabulary!$I$5:$I$7,K250)=1,COUNTIF(Vocabulary!$J$5:$J$6,L250)=1),"OK","UNRECOGNISED_ROUTING_VALUE"))

Sheet Candidate_Register
A1: Candidate and Scope Register - AF v6.2
A3: Candidate_ID | B3: Candidate_Name | C3: Version_or_Hash | D3: Architecture_Family | E3: Declared_Authority_Claim | F3: Scope_ID | G3: Population | H3: Jurisdiction_or_Community | I3: Evidence_Cutoff | J3: Candidate_Contact | K3: Affected_Party_Liaison | L3: Access_Needs | M3: Data_Sovereignty_Constraints | N3: Profile | O3: Record_Status
A4: SYNTH-CAND-HC | B4: Synthetic benefits architecture | C4: hash:illustrative | D4: legal-institutional | E4: Advisory recommendation only | F4: SCOPE-ILL-001 | G4: Synthetic national population | H4: Synthetic jurisdiction | I4: 2026-08-11 | J4: candidate@example.invalid | K4: liaison@example.invalid | L4: Interpretation and accessible formats | M4: No raw community evidence outside host repository | N4: AF-High-Consequence | O4: Illustrative

Sheet Stage_A
A1: Stage A Non-Compensatory Eligibility Record - AF v6.2
A3: Review_ID | B3: Candidate_ID | C3: Scope_ID | D3: Profile | E3: Evidence_Cutoff | F3: Host_ID | G3: Independence_Dossier_ID | H3: Administration_Valid | I3: Burden_Feasibility | J3: Protected_Floor_Unresolved | K3: C0_Inspectability | L3: C1_Rights | M3: C2_Auditability | N3: C3_Measurement | O3: C4_Corrigibility | P3: C5_Refusal_Authority | Q3: Derived_Overall_Status | R3: Recorded_Overall_Status | S3: Status_Match | T3: Public_Status_String | U3: Root_Cause_Map_ID | V3: Dissent_Refs | W3: Affected_Party_Refs | X3: Appeal_Route | Y3: Issued_At | Z3: Expiry_or_Requalification | AA3: Unpatchable_Count | AB3: Patchable_Count | AC3: Indeterminate_Count | AD3: Controlled_Adequacy_Count | AE3: Eligibility_Gate | AF3: Canonical_Status_Token | AG3: Public_String_Check | AH3: Adequate_Count | AI3: Criterion_Value_Check | AJ3: Administrative_Disposition | AK3: Protocol_Version | AL3: Constitutional_Legitimacy_Basis | AM3: Administrative_Disposition_Check
A4: SAR-ILL-001 | B4: SYNTH-CAND-HC | C4: SCOPE-ILL-001 | D4: AF-High-Consequence | E4: 2026-08-11 | F4: HOST-INDEPENDENT-01 | G4: IND-ILL-001 | H4: Yes | I4: Feasible with verified support | J4: No | K4: Adequate for scope | L4: Adequate for scope | M4: Adequate for scope | N4: Material defect - patchable | O4: Adequate for scope | P4: Adequate for scope | Q4: =IF(AE4="","",IF(AE4="ADMIN_DISPOSITION",AJ4,IF(OR(AE4="ADMIN_INCOMPLETE",AE4="ADMIN_INVALID",AE4="BURDEN_NOT_FEASIBLE",AE4="UNRECOGNISED_VALUE",AE4="UNRECOGNISED_ADMIN_DISPOSITION"),"Protocol refusal to evaluate",IF(AA4>0,"Stage-A non-admissible - unpatchable for stated claim",IF(AB4>0,"Stage-A non-admissible - patchable",IF(OR(J4="Yes",I4="Indeterminate",AC4>0),"Indeterminate - insufficient evidence",IF(AND(AH4=6,AD4=0),"Stage-A admissible - scoped",IF(AND(AH4+AD4=6,AD4>0),"Stage-A admissible - scoped, control-dependent","Protocol refusal to evaluate")))))))) | R4: Stage-A non-admissible - patchable | S4: =IF(AND(Q4="",R4=""),"",IF(AND(Q4<>"",R4=""),"UNRECORDED",IF(AND(Q4="",R4<>""),"ORPHAN_RECORDED",IF(Q4=R4,"MATCH","MISMATCH")))) | T4: Stage-A non-admissible - patchable | token=stage_a_non_admissible_patchable; | Candidate SYNTH-CAND-HC | Scope SCOPE-ILL-001 | Evidence cutoff 2026-08-11 | AF v6.2 | CL basis=CL1 self-assessment; CL2 design materials only; | U4: RCM-ILL-001 | V4: DISSENT-ILL-001 | W4: AP-ILL-001 | X4: Independent appeal panel | Y4: 2026-08-11 12:00Z | Z4: 2027-02-11 12:00Z | AA4: =COUNTIF(K4:P4,"Material defect - unpatchable for stated claim") | AB4: =COUNTIF(K4:P4,"Material defect - patchable") | AC4: =COUNTIF(K4:P4,"Indeterminate")+COUNTIF(K4:P4,"Not reviewed") | AD4: =COUNTIF(K4:P4,"Adequate - control-dependent") | AE4: =IF(COUNTA(A4:P4)+COUNTA(AJ4)=0,"",IF(AM4<>"OK","UNRECOGNISED_ADMIN_DISPOSITION",IF(AND(AJ4<>"",AJ4<>"None"),IF(OR(LEN(TRIM(A4))=0,LEN(TRIM(B4))=0,LEN(TRIM(C4))=0,LEN(TRIM(F4))=0),"ADMIN_INCOMPLETE","ADMIN_DISPOSITION"),IF(OR(LEN(TRIM(A4))=0,LEN(TRIM(B4))=0,LEN(TRIM(C4))=0,LEN(TRIM(D4))=0,LEN(TRIM(E4))=0,LEN(TRIM(F4))=0,LEN(TRIM(G4))=0,LEN(TRIM(H4))=0,LEN(TRIM(I4))=0,LEN(TRIM(J4))=0,LEN(TRIM(K4))=0,LEN(TRIM(L4))=0,LEN(TRIM(M4))=0,LEN(TRIM(N4))=0,LEN(TRIM(O4))=0,LEN(TRIM(P4))=0),"ADMIN_INCOMPLETE",IF(H4<>"Yes","ADMIN_INVALID",IF(I4="Not feasible","BURDEN_NOT_FEASIBLE",IF(AI4<>"OK","UNRECOGNISED_VALUE","CLEAR"))))))) | AF4: =IF(AND(Q4="",R4=""),"",IF(IF(Q4<>"",Q4,R4)="Stage-A admissible - scoped","stage_a_admissible_scoped",IF(IF(Q4<>"",Q4,R4)="Stage-A admissible - scoped, control-dependent","stage_a_admissible_scoped_control_dependent",IF(IF(Q4<>"",Q4,R4)="Stage-A non-admissible - patchable","stage_a_non_admissible_patchable",IF(IF(Q4<>"",Q4,R4)="Stage-A non-admissible - unpatchable for stated claim","stage_a_non_admissible_unpatchable_for_stated_claim",IF(IF(Q4<>"",Q4,R4)="Indeterminate - insufficient evidence","indeterminate_insufficient_evidence",IF(IF(Q4<>"",Q4,R4)="Protocol refusal to evaluate","protocol_refusal_to_evaluate",IF(IF(Q4<>"",Q4,R4)="Out of scope","out_of_scope",IF(IF(Q4<>"",Q4,R4)="Withdrawn","withdrawn",IF(IF(Q4<>"",Q4,R4)="Not reviewed","not_reviewed","unknown_status")))))))))) | AG4: =IF(AND(AF4="",T4=""),"",IF(AND(AF4<>"",ISNUMBER(SEARCH("token="&AF4&";",T4)),ISNUMBER(SEARCH(AK4,T4)),ISNUMBER(SEARCH("CL basis="&AL4&";",T4))),"VALID","INVALID_OR_INCOMPLETE")) | AH4: =COUNTIF(K4:P4,"Adequate for scope") | AI4: =IF(COUNTA(K4:P4)=0,"",IF(AA4+AB4+AC4+AD4+AH4=6,"OK","UNRECOGNISED_VALUE")) | AK4: =IF(A4="","",Vocabulary!$B$5) | AL4: =IF(A4="","",Vocabulary!$B$6) | AM4: =IF(AJ4="","OK",IF(COUNTIF(Vocabulary!$O$5:$O$8,AJ4)=1,"OK","UNRECOGNISED_ADMIN_DISPOSITION"))
Q5: =IF(AE5="","",IF(AE5="ADMIN_DISPOSITION",AJ5,IF(OR(AE5="ADMIN_INCOMPLETE",AE5="ADMIN_INVALID",AE5="BURDEN_NOT_FEASIBLE",AE5="UNRECOGNISED_VALUE",AE5="UNRECOGNISED_ADMIN_DISPOSITION"),"Protocol refusal to evaluate",IF(AA5>0,"Stage-A non-admissible - unpatchable for stated claim",IF(AB5>0,"Stage-A non-admissible - patchable",IF(OR(J5="Yes",I5="Indeterminate",AC5>0),"Indeterminate - insufficient evidence",IF(AND(AH5=6,AD5=0),"Stage-A admissible - scoped",IF(AND(AH5+AD5=6,AD5>0),"Stage-A admissible - scoped, control-dependent","Protocol refusal to evaluate")))))))) | S5: =IF(AND(Q5="",R5=""),"",IF(AND(Q5<>"",R5=""),"UNRECORDED",IF(AND(Q5="",R5<>""),"ORPHAN_RECORDED",IF(Q5=R5,"MATCH","MISMATCH")))) | AA5: =COUNTIF(K5:P5,"Material defect - unpatchable for stated claim") | AB5: =COUNTIF(K5:P5,"Material defect - patchable") | AC5: =COUNTIF(K5:P5,"Indeterminate")+COUNTIF(K5:P5,"Not reviewed") | AD5: =COUNTIF(K5:P5,"Adequate - control-dependent") | AE5: =IF(COUNTA(A5:P5)+COUNTA(AJ5)=0,"",IF(AM5<>"OK","UNRECOGNISED_ADMIN_DISPOSITION",IF(AND(AJ5<>"",AJ5<>"None"),IF(OR(LEN(TRIM(A5))=0,LEN(TRIM(B5))=0,LEN(TRIM(C5))=0,LEN(TRIM(F5))=0),"ADMIN_INCOMPLETE","ADMIN_DISPOSITION"),IF(OR(LEN(TRIM(A5))=0,LEN(TRIM(B5))=0,LEN(TRIM(C5))=0,LEN(TRIM(D5))=0,LEN(TRIM(E5))=0,LEN(TRIM(F5))=0,LEN(TRIM(G5))=0,LEN(TRIM(H5))=0,LEN(TRIM(I5))=0,LEN(TRIM(J5))=0,LEN(TRIM(K5))=0,LEN(TRIM(L5))=0,LEN(TRIM(M5))=0,LEN(TRIM(N5))=0,LEN(TRIM(O5))=0,LEN(TRIM(P5))=0),"ADMIN_INCOMPLETE",IF(H5<>"Yes","ADMIN_INVALID",IF(I5="Not feasible","BURDEN_NOT_FEASIBLE",IF(AI5<>"OK","UNRECOGNISED_VALUE","CLEAR"))))))) | AF5: =IF(AND(Q5="",R5=""),"",IF(IF(Q5<>"",Q5,R5)="Stage-A admissible - scoped","stage_a_admissible_scoped",IF(IF(Q5<>"",Q5,R5)="Stage-A admissible - scoped, control-dependent","stage_a_admissible_scoped_control_dependent",IF(IF(Q5<>"",Q5,R5)="Stage-A non-admissible - patchable","stage_a_non_admissible_patchable",IF(IF(Q5<>"",Q5,R5)="Stage-A non-admissible - unpatchable for stated claim","stage_a_non_admissible_unpatchable_for_stated_claim",IF(IF(Q5<>"",Q5,R5)="Indeterminate - insufficient evidence","indeterminate_insufficient_evidence",IF(IF(Q5<>"",Q5,R5)="Protocol refusal to evaluate","protocol_refusal_to_evaluate",IF(IF(Q5<>"",Q5,R5)="Out of scope","out_of_scope",IF(IF(Q5<>"",Q5,R5)="Withdrawn","withdrawn",IF(IF(Q5<>"",Q5,R5)="Not reviewed","not_reviewed","unknown_status")))))))))) | AG5: =IF(AND(AF5="",T5=""),"",IF(AND(AF5<>"",ISNUMBER(SEARCH("token="&AF5&";",T5)),ISNUMBER(SEARCH(AK5,T5)),ISNUMBER(SEARCH("CL basis="&AL5&";",T5))),"VALID","INVALID_OR_INCOMPLETE")) | AH5: =COUNTIF(K5:P5,"Adequate for scope") | AI5: =IF(COUNTA(K5:P5)=0,"",IF(AA5+AB5+AC5+AD5+AH5=6,"OK","UNRECOGNISED_VALUE")) | AK5: =IF(A5="","",Vocabulary!$B$5) | AL5: =IF(A5="","",Vocabulary!$B$6) | AM5: =IF(AJ5="","OK",IF(COUNTIF(Vocabulary!$O$5:$O$8,AJ5)=1,"OK","UNRECOGNISED_ADMIN_DISPOSITION"))
Q6: =IF(AE6="","",IF(AE6="ADMIN_DISPOSITION",AJ6,IF(OR(AE6="ADMIN_INCOMPLETE",AE6="ADMIN_INVALID",AE6="BURDEN_NOT_FEASIBLE",AE6="UNRECOGNISED_VALUE",AE6="UNRECOGNISED_ADMIN_DISPOSITION"),"Protocol refusal to evaluate",IF(AA6>0,"Stage-A non-admissible - unpatchable for stated claim",IF(AB6>0,"Stage-A non-admissible - patchable",IF(OR(J6="Yes",I6="Indeterminate",AC6>0),"Indeterminate - insufficient evidence",IF(AND(AH6=6,AD6=0),"Stage-A admissible - scoped",IF(AND(AH6+AD6=6,AD6>0),"Stage-A admissible - scoped, control-dependent","Protocol refusal to evaluate")))))))) | S6: =IF(AND(Q6="",R6=""),"",IF(AND(Q6<>"",R6=""),"UNRECORDED",IF(AND(Q6="",R6<>""),"ORPHAN_RECORDED",IF(Q6=R6,"MATCH","MISMATCH")))) | AA6: =COUNTIF(K6:P6,"Material defect - unpatchable for stated claim") | AB6: =COUNTIF(K6:P6,"Material defect - patchable") | AC6: =COUNTIF(K6:P6,"Indeterminate")+COUNTIF(K6:P6,"Not reviewed") | AD6: =COUNTIF(K6:P6,"Adequate - control-dependent") | AE6: =IF(COUNTA(A6:P6)+COUNTA(AJ6)=0,"",IF(AM6<>"OK","UNRECOGNISED_ADMIN_DISPOSITION",IF(AND(AJ6<>"",AJ6<>"None"),IF(OR(LEN(TRIM(A6))=0,LEN(TRIM(B6))=0,LEN(TRIM(C6))=0,LEN(TRIM(F6))=0),"ADMIN_INCOMPLETE","ADMIN_DISPOSITION"),IF(OR(LEN(TRIM(A6))=0,LEN(TRIM(B6))=0,LEN(TRIM(C6))=0,LEN(TRIM(D6))=0,LEN(TRIM(E6))=0,LEN(TRIM(F6))=0,LEN(TRIM(G6))=0,LEN(TRIM(H6))=0,LEN(TRIM(I6))=0,LEN(TRIM(J6))=0,LEN(TRIM(K6))=0,LEN(TRIM(L6))=0,LEN(TRIM(M6))=0,LEN(TRIM(N6))=0,LEN(TRIM(O6))=0,LEN(TRIM(P6))=0),"ADMIN_INCOMPLETE",IF(H6<>"Yes","ADMIN_INVALID",IF(I6="Not feasible","BURDEN_NOT_FEASIBLE",IF(AI6<>"OK","UNRECOGNISED_VALUE","CLEAR"))))))) | AF6: =IF(AND(Q6="",R6=""),"",IF(IF(Q6<>"",Q6,R6)="Stage-A admissible - scoped","stage_a_admissible_scoped",IF(IF(Q6<>"",Q6,R6)="Stage-A admissible - scoped, control-dependent","stage_a_admissible_scoped_control_dependent",IF(IF(Q6<>"",Q6,R6)="Stage-A non-admissible - patchable","stage_a_non_admissible_patchable",IF(IF(Q6<>"",Q6,R6)="Stage-A non-admissible - unpatchable for stated claim","stage_a_non_admissible_unpatchable_for_stated_claim",IF(IF(Q6<>"",Q6,R6)="Indeterminate - insufficient evidence","indeterminate_insufficient_evidence",IF(IF(Q6<>"",Q6,R6)="Protocol refusal to evaluate","protocol_refusal_to_evaluate",IF(IF(Q6<>"",Q6,R6)="Out of scope","out_of_scope",IF(IF(Q6<>"",Q6,R6)="Withdrawn","withdrawn",IF(IF(Q6<>"",Q6,R6)="Not reviewed","not_reviewed","unknown_status")))))))))) | AG6: =IF(AND(AF6="",T6=""),"",IF(AND(AF6<>"",ISNUMBER(SEARCH("token="&AF6&";",T6)),ISNUMBER(SEARCH(AK6,T6)),ISNUMBER(SEARCH("CL basis="&AL6&";",T6))),"VALID","INVALID_OR_INCOMPLETE")) | AH6: =COUNTIF(K6:P6,"Adequate for scope") | AI6: =IF(COUNTA(K6:P6)=0,"",IF(AA6+AB6+AC6+AD6+AH6=6,"OK","UNRECOGNISED_VALUE")) | AK6: =IF(A6="","",Vocabulary!$B$5) | AL6: =IF(A6="","",Vocabulary!$B$6) | AM6: =IF(AJ6="","OK",IF(COUNTIF(Vocabulary!$O$5:$O$8,AJ6)=1,"OK","UNRECOGNISED_ADMIN_DISPOSITION"))
Q7: =IF(AE7="","",IF(AE7="ADMIN_DISPOSITION",AJ7,IF(OR(AE7="ADMIN_INCOMPLETE",AE7="ADMIN_INVALID",AE7="BURDEN_NOT_FEASIBLE",AE7="UNRECOGNISED_VALUE",AE7="UNRECOGNISED_ADMIN_DISPOSITION"),"Protocol refusal to evaluate",IF(AA7>0,"Stage-A non-admissible - unpatchable for stated claim",IF(AB7>0,"Stage-A non-admissible - patchable",IF(OR(J7="Yes",I7="Indeterminate",AC7>0),"Indeterminate - insufficient evidence",IF(AND(AH7=6,AD7=0),"Stage-A admissible - scoped",IF(AND(AH7+AD7=6,AD7>0),"Stage-A admissible - scoped, control-dependent","Protocol refusal to evaluate")))))))) | S7: =IF(AND(Q7="",R7=""),"",IF(AND(Q7<>"",R7=""),"UNRECORDED",IF(AND(Q7="",R7<>""),"ORPHAN_RECORDED",IF(Q7=R7,"MATCH","MISMATCH")))) | AA7: =COUNTIF(K7:P7,"Material defect - unpatchable for stated claim") | AB7: =COUNTIF(K7:P7,"Material defect - patchable") | AC7: =COUNTIF(K7:P7,"Indeterminate")+COUNTIF(K7:P7,"Not reviewed") | AD7: =COUNTIF(K7:P7,"Adequate - control-dependent") | AE7: =IF(COUNTA(A7:P7)+COUNTA(AJ7)=0,"",IF(AM7<>"OK","UNRECOGNISED_ADMIN_DISPOSITION",IF(AND(AJ7<>"",AJ7<>"None"),IF(OR(LEN(TRIM(A7))=0,LEN(TRIM(B7))=0,LEN(TRIM(C7))=0,LEN(TRIM(F7))=0),"ADMIN_INCOMPLETE","ADMIN_DISPOSITION"),IF(OR(LEN(TRIM(A7))=0,LEN(TRIM(B7))=0,LEN(TRIM(C7))=0,LEN(TRIM(D7))=0,LEN(TRIM(E7))=0,LEN(TRIM(F7))=0,LEN(TRIM(G7))=0,LEN(TRIM(H7))=0,LEN(TRIM(I7))=0,LEN(TRIM(J7))=0,LEN(TRIM(K7))=0,LEN(TRIM(L7))=0,LEN(TRIM(M7))=0,LEN(TRIM(N7))=0,LEN(TRIM(O7))=0,LEN(TRIM(P7))=0),"ADMIN_INCOMPLETE",IF(H7<>"Yes","ADMIN_INVALID",IF(I7="Not feasible","BURDEN_NOT_FEASIBLE",IF(AI7<>"OK","UNRECOGNISED_VALUE","CLEAR"))))))) | AF7: =IF(AND(Q7="",R7=""),"",IF(IF(Q7<>"",Q7,R7)="Stage-A admissible - scoped","stage_a_admissible_scoped",IF(IF(Q7<>"",Q7,R7)="Stage-A admissible - scoped, control-dependent","stage_a_admissible_scoped_control_dependent",IF(IF(Q7<>"",Q7,R7)="Stage-A non-admissible - patchable","stage_a_non_admissible_patchable",IF(IF(Q7<>"",Q7,R7)="Stage-A non-admissible - unpatchable for stated claim","stage_a_non_admissible_unpatchable_for_stated_claim",IF(IF(Q7<>"",Q7,R7)="Indeterminate - insufficient evidence","indeterminate_insufficient_evidence",IF(IF(Q7<>"",Q7,R7)="Protocol refusal to evaluate","protocol_refusal_to_evaluate",IF(IF(Q7<>"",Q7,R7)="Out of scope","out_of_scope",IF(IF(Q7<>"",Q7,R7)="Withdrawn","withdrawn",IF(IF(Q7<>"",Q7,R7)="Not reviewed","not_reviewed","unknown_status")))))))))) | AG7: =IF(AND(AF7="",T7=""),"",IF(AND(AF7<>"",ISNUMBER(SEARCH("token="&AF7&";",T7)),ISNUMBER(SEARCH(AK7,T7)),ISNUMBER(SEARCH("CL basis="&AL7&";",T7))),"VALID","INVALID_OR_INCOMPLETE")) | AH7: =COUNTIF(K7:P7,"Adequate for scope") | AI7: =IF(COUNTA(K7:P7)=0,"",IF(AA7+AB7+AC7+AD7+AH7=6,"OK","UNRECOGNISED_VALUE")) | AK7: =IF(A7="","",Vocabulary!$B$5) | AL7: =IF(A7="","",Vocabulary!$B$6) | AM7: =IF(AJ7="","OK",IF(COUNTIF(Vocabulary!$O$5:$O$8,AJ7)=1,"OK","UNRECOGNISED_ADMIN_DISPOSITION"))
Q8: =IF(AE8="","",IF(AE8="ADMIN_DISPOSITION",AJ8,IF(OR(AE8="ADMIN_INCOMPLETE",AE8="ADMIN_INVALID",AE8="BURDEN_NOT_FEASIBLE",AE8="UNRECOGNISED_VALUE",AE8="UNRECOGNISED_ADMIN_DISPOSITION"),"Protocol refusal to evaluate",IF(AA8>0,"Stage-A non-admissible - unpatchable for stated claim",IF(AB8>0,"Stage-A non-admissible - patchable",IF(OR(J8="Yes",I8="Indeterminate",AC8>0),"Indeterminate - insufficient evidence",IF(AND(AH8=6,AD8=0),"Stage-A admissible - scoped",IF(AND(AH8+AD8=6,AD8>0),"Stage-A admissible - scoped, control-dependent","Protocol refusal to evaluate")))))))) | S8: =IF(AND(Q8="",R8=""),"",IF(AND(Q8<>"",R8=""),"UNRECORDED",IF(AND(Q8="",R8<>""),"ORPHAN_RECORDED",IF(Q8=R8,"MATCH","MISMATCH")))) | AA8: =COUNTIF(K8:P8,"Material defect - unpatchable for stated claim") | AB8: =COUNTIF(K8:P8,"Material defect - patchable") | AC8: =COUNTIF(K8:P8,"Indeterminate")+COUNTIF(K8:P8,"Not reviewed") | AD8: =COUNTIF(K8:P8,"Adequate - control-dependent") | AE8: =IF(COUNTA(A8:P8)+COUNTA(AJ8)=0,"",IF(AM8<>"OK","UNRECOGNISED_ADMIN_DISPOSITION",IF(AND(AJ8<>"",AJ8<>"None"),IF(OR(LEN(TRIM(A8))=0,LEN(TRIM(B8))=0,LEN(TRIM(C8))=0,LEN(TRIM(F8))=0),"ADMIN_INCOMPLETE","ADMIN_DISPOSITION"),IF(OR(LEN(TRIM(A8))=0,LEN(TRIM(B8))=0,LEN(TRIM(C8))=0,LEN(TRIM(D8))=0,LEN(TRIM(E8))=0,LEN(TRIM(F8))=0,LEN(TRIM(G8))=0,LEN(TRIM(H8))=0,LEN(TRIM(I8))=0,LEN(TRIM(J8))=0,LEN(TRIM(K8))=0,LEN(TRIM(L8))=0,LEN(TRIM(M8))=0,LEN(TRIM(N8))=0,LEN(TRIM(O8))=0,LEN(TRIM(P8))=0),"ADMIN_INCOMPLETE",IF(H8<>"Yes","ADMIN_INVALID",IF(I8="Not feasible","BURDEN_NOT_FEASIBLE",IF(AI8<>"OK","UNRECOGNISED_VALUE","CLEAR"))))))) | AF8: =IF(AND(Q8="",R8=""),"",IF(IF(Q8<>"",Q8,R8)="Stage-A admissible - scoped","stage_a_admissible_scoped",IF(IF(Q8<>"",Q8,R8)="Stage-A admissible - scoped, control-dependent","stage_a_admissible_scoped_control_dependent",IF(IF(Q8<>"",Q8,R8)="Stage-A non-admissible - patchable","stage_a_non_admissible_patchable",IF(IF(Q8<>"",Q8,R8)="Stage-A non-admissible - unpatchable for stated claim","stage_a_non_admissible_unpatchable_for_stated_claim",IF(IF(Q8<>"",Q8,R8)="Indeterminate - insufficient evidence","indeterminate_insufficient_evidence",IF(IF(Q8<>"",Q8,R8)="Protocol refusal to evaluate","protocol_refusal_to_evaluate",IF(IF(Q8<>"",Q8,R8)="Out of scope","out_of_scope",IF(IF(Q8<>"",Q8,R8)="Withdrawn","withdrawn",IF(IF(Q8<>"",Q8,R8)="Not reviewed","not_reviewed","unknown_status")))))))))) | AG8: =IF(AND(AF8="",T8=""),"",IF(AND(AF8<>"",ISNUMBER(SEARCH("token="&AF8&";",T8)),ISNUMBER(SEARCH(AK8,T8)),ISNUMBER(SEARCH("CL basis="&AL8&";",T8))),"VALID","INVALID_OR_INCOMPLETE")) | AH8: =COUNTIF(K8:P8,"Adequate for scope") | AI8: =IF(COUNTA(K8:P8)=0,"",IF(AA8+AB8+AC8+AD8+AH8=6,"OK","UNRECOGNISED_VALUE")) | AK8: =IF(A8="","",Vocabulary!$B$5) | AL8: =IF(A8="","",Vocabulary!$B$6) | AM8: =IF(AJ8="","OK",IF(COUNTIF(Vocabulary!$O$5:$O$8,AJ8)=1,"OK","UNRECOGNISED_ADMIN_DISPOSITION"))
Q9: =IF(AE9="","",IF(AE9="ADMIN_DISPOSITION",AJ9,IF(OR(AE9="ADMIN_INCOMPLETE",AE9="ADMIN_INVALID",AE9="BURDEN_NOT_FEASIBLE",AE9="UNRECOGNISED_VALUE",AE9="UNRECOGNISED_ADMIN_DISPOSITION"),"Protocol refusal to evaluate",IF(AA9>0,"Stage-A non-admissible - unpatchable for stated claim",IF(AB9>0,"Stage-A non-admissible - patchable",IF(OR(J9="Yes",I9="Indeterminate",AC9>0),"Indeterminate - insufficient evidence",IF(AND(AH9=6,AD9=0),"Stage-A admissible - scoped",IF(AND(AH9+AD9=6,AD9>0),"Stage-A admissible - scoped, control-dependent","Protocol refusal to evaluate")))))))) | S9: =IF(AND(Q9="",R9=""),"",IF(AND(Q9<>"",R9=""),"UNRECORDED",IF(AND(Q9="",R9<>""),"ORPHAN_RECORDED",IF(Q9=R9,"MATCH","MISMATCH")))) | AA9: =COUNTIF(K9:P9,"Material defect - unpatchable for stated claim") | AB9: =COUNTIF(K9:P9,"Material defect - patchable") | AC9: =COUNTIF(K9:P9,"Indeterminate")+COUNTIF(K9:P9,"Not reviewed") | AD9: =COUNTIF(K9:P9,"Adequate - control-dependent") | AE9: =IF(COUNTA(A9:P9)+COUNTA(AJ9)=0,"",IF(AM9<>"OK","UNRECOGNISED_ADMIN_DISPOSITION",IF(AND(AJ9<>"",AJ9<>"None"),IF(OR(LEN(TRIM(A9))=0,LEN(TRIM(B9))=0,LEN(TRIM(C9))=0,LEN(TRIM(F9))=0),"ADMIN_INCOMPLETE","ADMIN_DISPOSITION"),IF(OR(LEN(TRIM(A9))=0,LEN(TRIM(B9))=0,LEN(TRIM(C9))=0,LEN(TRIM(D9))=0,LEN(TRIM(E9))=0,LEN(TRIM(F9))=0,LEN(TRIM(G9))=0,LEN(TRIM(H9))=0,LEN(TRIM(I9))=0,LEN(TRIM(J9))=0,LEN(TRIM(K9))=0,LEN(TRIM(L9))=0,LEN(TRIM(M9))=0,LEN(TRIM(N9))=0,LEN(TRIM(O9))=0,LEN(TRIM(P9))=0),"ADMIN_INCOMPLETE",IF(H9<>"Yes","ADMIN_INVALID",IF(I9="Not feasible","BURDEN_NOT_FEASIBLE",IF(AI9<>"OK","UNRECOGNISED_VALUE","CLEAR"))))))) | AF9: =IF(AND(Q9="",R9=""),"",IF(IF(Q9<>"",Q9,R9)="Stage-A admissible - scoped","stage_a_admissible_scoped",IF(IF(Q9<>"",Q9,R9)="Stage-A admissible - scoped, control-dependent","stage_a_admissible_scoped_control_dependent",IF(IF(Q9<>"",Q9,R9)="Stage-A non-admissible - patchable","stage_a_non_admissible_patchable",IF(IF(Q9<>"",Q9,R9)="Stage-A non-admissible - unpatchable for stated claim","stage_a_non_admissible_unpatchable_for_stated_claim",IF(IF(Q9<>"",Q9,R9)="Indeterminate - insufficient evidence","indeterminate_insufficient_evidence",IF(IF(Q9<>"",Q9,R9)="Protocol refusal to evaluate","protocol_refusal_to_evaluate",IF(IF(Q9<>"",Q9,R9)="Out of scope","out_of_scope",IF(IF(Q9<>"",Q9,R9)="Withdrawn","withdrawn",IF(IF(Q9<>"",Q9,R9)="Not reviewed","not_reviewed","unknown_status")))))))))) | AG9: =IF(AND(AF9="",T9=""),"",IF(AND(AF9<>"",ISNUMBER(SEARCH("token="&AF9&";",T9)),ISNUMBER(SEARCH(AK9,T9)),ISNUMBER(SEARCH("CL basis="&AL9&";",T9))),"VALID","INVALID_OR_INCOMPLETE")) | AH9: =COUNTIF(K9:P9,"Adequate for scope") | AI9: =IF(COUNTA(K9:P9)=0,"",IF(AA9+AB9+AC9+AD9+AH9=6,"OK","UNRECOGNISED_VALUE")) | AK9: =IF(A9="","",Vocabulary!$B$5) | AL9: =IF(A9="","",Vocabulary!$B$6) | AM9: =IF(AJ9="","OK",IF(COUNTIF(Vocabulary!$O$5:$O$8,AJ9)=1,"OK","UNRECOGNISED_ADMIN_DISPOSITION"))
Q10: =IF(AE10="","",IF(AE10="ADMIN_DISPOSITION",AJ10,IF(OR(AE10="ADMIN_INCOMPLETE",AE10="ADMIN_INVALID",AE10="BURDEN_NOT_FEASIBLE",AE10="UNRECOGNISED_VALUE",AE10="UNRECOGNISED_ADMIN_DISPOSITION"),"Protocol refusal to evaluate",IF(AA10>0,"Stage-A non-admissible - unpatchable for stated claim",IF(AB10>0,"Stage-A non-admissible - patchable",IF(OR(J10="Yes",I10="Indeterminate",AC10>0),"Indeterminate - insufficient evidence",IF(AND(AH10=6,AD10=0),"Stage-A admissible - scoped",IF(AND(AH10+AD10=6,AD10>0),"Stage-A admissible - scoped, control-dependent","Protocol refusal to evaluate")))))))) | S10: =IF(AND(Q10="",R10=""),"",IF(AND(Q10<>"",R10=""),"UNRECORDED",IF(AND(Q10="",R10<>""),"ORPHAN_RECORDED",IF(Q10=R10,"MATCH","MISMATCH")))) | AA10: =COUNTIF(K10:P10,"Material defect - unpatchable for stated claim") | AB10: =COUNTIF(K10:P10,"Material defect - patchable") | AC10: =COUNTIF(K10:P10,"Indeterminate")+COUNTIF(K10:P10,"Not reviewed") | AD10: =COUNTIF(K10:P10,"Adequate - control-dependent") | AE10: =IF(COUNTA(A10:P10)+COUNTA(AJ10)=0,"",IF(AM10<>"OK","UNRECOGNISED_ADMIN_DISPOSITION",IF(AND(AJ10<>"",AJ10<>"None"),IF(OR(LEN(TRIM(A10))=0,LEN(TRIM(B10))=0,LEN(TRIM(C10))=0,LEN(TRIM(F10))=0),"ADMIN_INCOMPLETE","ADMIN_DISPOSITION"),IF(OR(LEN(TRIM(A10))=0,LEN(TRIM(B10))=0,LEN(TRIM(C10))=0,LEN(TRIM(D10))=0,LEN(TRIM(E10))=0,LEN(TRIM(F10))=0,LEN(TRIM(G10))=0,LEN(TRIM(H10))=0,LEN(TRIM(I10))=0,LEN(TRIM(J10))=0,LEN(TRIM(K10))=0,LEN(TRIM(L10))=0,LEN(TRIM(M10))=0,LEN(TRIM(N10))=0,LEN(TRIM(O10))=0,LEN(TRIM(P10))=0),"ADMIN_INCOMPLETE",IF(H10<>"Yes","ADMIN_INVALID",IF(I10="Not feasible","BURDEN_NOT_FEASIBLE",IF(AI10<>"OK","UNRECOGNISED_VALUE","CLEAR"))))))) | AF10: =IF(AND(Q10="",R10=""),"",IF(IF(Q10<>"",Q10,R10)="Stage-A admissible - scoped","stage_a_admissible_scoped",IF(IF(Q10<>"",Q10,R10)="Stage-A admissible - scoped, control-dependent","stage_a_admissible_scoped_control_dependent",IF(IF(Q10<>"",Q10,R10)="Stage-A non-admissible - patchable","stage_a_non_admissible_patchable",IF(IF(Q10<>"",Q10,R10)="Stage-A non-admissible - unpatchable for stated claim","stage_a_non_admissible_unpatchable_for_stated_claim",IF(IF(Q10<>"",Q10,R10)="Indeterminate - insufficient evidence","indeterminate_insufficient_evidence",IF(IF(Q10<>"",Q10,R10)="Protocol refusal to evaluate","protocol_refusal_to_evaluate",IF(IF(Q10<>"",Q10,R10)="Out of scope","out_of_scope",IF(IF(Q10<>"",Q10,R10)="Withdrawn","withdrawn",IF(IF(Q10<>"",Q10,R10)="Not reviewed","not_reviewed","unknown_status")))))))))) | AG10: =IF(AND(AF10="",T10=""),"",IF(AND(AF10<>"",ISNUMBER(SEARCH("token="&AF10&";",T10)),ISNUMBER(SEARCH(AK10,T10)),ISNUMBER(SEARCH("CL basis="&AL10&";",T10))),"VALID","INVALID_OR_INCOMPLETE")) | AH10: =COUNTIF(K10:P10,"Adequate for scope") | AI10: =IF(COUNTA(K10:P10)=0,"",IF(AA10+AB10+AC10+AD10+AH10=6,"OK","UNRECOGNISED_VALUE")) | AK10: =IF(A10="","",Vocabulary!$B$5) | AL10: =IF(A10="","",Vocabulary!$B$6) | AM10: =IF(AJ10="","OK",IF(COUNTIF(Vocabulary!$O$5:$O$8,AJ10)=1,"OK","UNRECOGNISED_ADMIN_DISPOSITION"))
Q11: =IF(AE11="","",IF(AE11="ADMIN_DISPOSITION",AJ11,IF(OR(AE11="ADMIN_INCOMPLETE",AE11="ADMIN_INVALID",AE11="BURDEN_NOT_FEASIBLE",AE11="UNRECOGNISED_VALUE",AE11="UNRECOGNISED_ADMIN_DISPOSITION"),"Protocol refusal to evaluate",IF(AA11>0,"Stage-A non-admissible - unpatchable for stated claim",IF(AB11>0,"Stage-A non-admissible - patchable",IF(OR(J11="Yes",I11="Indeterminate",AC11>0),"Indeterminate - insufficient evidence",IF(AND(AH11=6,AD11=0),"Stage-A admissible - scoped",IF(AND(AH11+AD11=6,AD11>0),"Stage-A admissible - scoped, control-dependent","Protocol refusal to evaluate")))))))) | S11: =IF(AND(Q11="",R11=""),"",IF(AND(Q11<>"",R11=""),"UNRECORDED",IF(AND(Q11="",R11<>""),"ORPHAN_RECORDED",IF(Q11=R11,"MATCH","MISMATCH")))) | AA11: =COUNTIF(K11:P11,"Material defect - unpatchable for stated claim") | AB11: =COUNTIF(K11:P11,"Material defect - patchable") | AC11: =COUNTIF(K11:P11,"Indeterminate")+COUNTIF(K11:P11,"Not reviewed") | AD11: =COUNTIF(K11:P11,"Adequate - control-dependent") | AE11: =IF(COUNTA(A11:P11)+COUNTA(AJ11)=0,"",IF(AM11<>"OK","UNRECOGNISED_ADMIN_DISPOSITION",IF(AND(AJ11<>"",AJ11<>"None"),IF(OR(LEN(TRIM(A11))=0,LEN(TRIM(B11))=0,LEN(TRIM(C11))=0,LEN(TRIM(F11))=0),"ADMIN_INCOMPLETE","ADMIN_DISPOSITION"),IF(OR(LEN(TRIM(A11))=0,LEN(TRIM(B11))=0,LEN(TRIM(C11))=0,LEN(TRIM(D11))=0,LEN(TRIM(E11))=0,LEN(TRIM(F11))=0,LEN(TRIM(G11))=0,LEN(TRIM(H11))=0,LEN(TRIM(I11))=0,LEN(TRIM(J11))=0,LEN(TRIM(K11))=0,LEN(TRIM(L11))=0,LEN(TRIM(M11))=0,LEN(TRIM(N11))=0,LEN(TRIM(O11))=0,LEN(TRIM(P11))=0),"ADMIN_INCOMPLETE",IF(H11<>"Yes","ADMIN_INVALID",IF(I11="Not feasible","BURDEN_NOT_FEASIBLE",IF(AI11<>"OK","UNRECOGNISED_VALUE","CLEAR"))))))) | AF11: =IF(AND(Q11="",R11=""),"",IF(IF(Q11<>"",Q11,R11)="Stage-A admissible - scoped","stage_a_admissible_scoped",IF(IF(Q11<>"",Q11,R11)="Stage-A admissible - scoped, control-dependent","stage_a_admissible_scoped_control_dependent",IF(IF(Q11<>"",Q11,R11)="Stage-A non-admissible - patchable","stage_a_non_admissible_patchable",IF(IF(Q11<>"",Q11,R11)="Stage-A non-admissible - unpatchable for stated claim","stage_a_non_admissible_unpatchable_for_stated_claim",IF(IF(Q11<>"",Q11,R11)="Indeterminate - insufficient evidence","indeterminate_insufficient_evidence",IF(IF(Q11<>"",Q11,R11)="Protocol refusal to evaluate","protocol_refusal_to_evaluate",IF(IF(Q11<>"",Q11,R11)="Out of scope","out_of_scope",IF(IF(Q11<>"",Q11,R11)="Withdrawn","withdrawn",IF(IF(Q11<>"",Q11,R11)="Not reviewed","not_reviewed","unknown_status")))))))))) | AG11: =IF(AND(AF11="",T11=""),"",IF(AND(AF11<>"",ISNUMBER(SEARCH("token="&AF11&";",T11)),ISNUMBER(SEARCH(AK11,T11)),ISNUMBER(SEARCH("CL basis="&AL11&";",T11))),"VALID","INVALID_OR_INCOMPLETE")) | AH11: =COUNTIF(K11:P11,"Adequate for scope") | AI11: =IF(COUNTA(K11:P11)=0,"",IF(AA11+AB11+AC11+AD11+AH11=6,"OK","UNRECOGNISED_VALUE")) | AK11: =IF(A11="","",Vocabulary!$B$5) | AL11: =IF(A11="","",Vocabulary!$B$6) | AM11: =IF(AJ11="","OK",IF(COUNTIF(Vocabulary!$O$5:$O$8,AJ11)=1,"OK","UNRECOGNISED_ADMIN_DISPOSITION"))
Q12: =IF(AE12="","",IF(AE12="ADMIN_DISPOSITION",AJ12,IF(OR(AE12="ADMIN_INCOMPLETE",AE12="ADMIN_INVALID",AE12="BURDEN_NOT_FEASIBLE",AE12="UNRECOGNISED_VALUE",AE12="UNRECOGNISED_ADMIN_DISPOSITION"),"Protocol refusal to evaluate",IF(AA12>0,"Stage-A non-admissible - unpatchable for stated claim",IF(AB12>0,"Stage-A non-admissible - patchable",IF(OR(J12="Yes",I12="Indeterminate",AC12>0),"Indeterminate - insufficient evidence",IF(AND(AH12=6,AD12=0),"Stage-A admissible - scoped",IF(AND(AH12+AD12=6,AD12>0),"Stage-A admissible - scoped, control-dependent","Protocol refusal to evaluate")))))))) | S12: =IF(AND(Q12="",R12=""),"",IF(AND(Q12<>"",R12=""),"UNRECORDED",IF(AND(Q12="",R12<>""),"ORPHAN_RECORDED",IF(Q12=R12,"MATCH","MISMATCH")))) | AA12: =COUNTIF(K12:P12,"Material defect - unpatchable for stated claim") | AB12: =COUNTIF(K12:P12,"Material defect - patchable") | AC12: =COUNTIF(K12:P12,"Indeterminate")+COUNTIF(K12:P12,"Not reviewed") | AD12: =COUNTIF(K12:P12,"Adequate - control-dependent") | AE12: =IF(COUNTA(A12:P12)+COUNTA(AJ12)=0,"",IF(AM12<>"OK","UNRECOGNISED_ADMIN_DISPOSITION",IF(AND(AJ12<>"",AJ12<>"None"),IF(OR(LEN(TRIM(A12))=0,LEN(TRIM(B12))=0,LEN(TRIM(C12))=0,LEN(TRIM(F12))=0),"ADMIN_INCOMPLETE","ADMIN_DISPOSITION"),IF(OR(LEN(TRIM(A12))=0,LEN(TRIM(B12))=0,LEN(TRIM(C12))=0,LEN(TRIM(D12))=0,LEN(TRIM(E12))=0,LEN(TRIM(F12))=0,LEN(TRIM(G12))=0,LEN(TRIM(H12))=0,LEN(TRIM(I12))=0,LEN(TRIM(J12))=0,LEN(TRIM(K12))=0,LEN(TRIM(L12))=0,LEN(TRIM(M12))=0,LEN(TRIM(N12))=0,LEN(TRIM(O12))=0,LEN(TRIM(P12))=0),"ADMIN_INCOMPLETE",IF(H12<>"Yes","ADMIN_INVALID",IF(I12="Not feasible","BURDEN_NOT_FEASIBLE",IF(AI12<>"OK","UNRECOGNISED_VALUE","CLEAR"))))))) | AF12: =IF(AND(Q12="",R12=""),"",IF(IF(Q12<>"",Q12,R12)="Stage-A admissible - scoped","stage_a_admissible_scoped",IF(IF(Q12<>"",Q12,R12)="Stage-A admissible - scoped, control-dependent","stage_a_admissible_scoped_control_dependent",IF(IF(Q12<>"",Q12,R12)="Stage-A non-admissible - patchable","stage_a_non_admissible_patchable",IF(IF(Q12<>"",Q12,R12)="Stage-A non-admissible - unpatchable for stated claim","stage_a_non_admissible_unpatchable_for_stated_claim",IF(IF(Q12<>"",Q12,R12)="Indeterminate - insufficient evidence","indeterminate_insufficient_evidence",IF(IF(Q12<>"",Q12,R12)="Protocol refusal to evaluate","protocol_refusal_to_evaluate",IF(IF(Q12<>"",Q12,R12)="Out of scope","out_of_scope",IF(IF(Q12<>"",Q12,R12)="Withdrawn","withdrawn",IF(IF(Q12<>"",Q12,R12)="Not reviewed","not_reviewed","unknown_status")))))))))) | AG12: =IF(AND(AF12="",T12=""),"",IF(AND(AF12<>"",ISNUMBER(SEARCH("token="&AF12&";",T12)),ISNUMBER(SEARCH(AK12,T12)),ISNUMBER(SEARCH("CL basis="&AL12&";",T12))),"VALID","INVALID_OR_INCOMPLETE")) | AH12: =COUNTIF(K12:P12,"Adequate for scope") | AI12: =IF(COUNTA(K12:P12)=0,"",IF(AA12+AB12+AC12+AD12+AH12=6,"OK","UNRECOGNISED_VALUE")) | AK12: =IF(A12="","",Vocabulary!$B$5) | AL12: =IF(A12="","",Vocabulary!$B$6) | AM12: =IF(AJ12="","OK",IF(COUNTIF(Vocabulary!$O$5:$O$8,AJ12)=1,"OK","UNRECOGNISED_ADMIN_DISPOSITION"))
Q13: =IF(AE13="","",IF(AE13="ADMIN_DISPOSITION",AJ13,IF(OR(AE13="ADMIN_INCOMPLETE",AE13="ADMIN_INVALID",AE13="BURDEN_NOT_FEASIBLE",AE13="UNRECOGNISED_VALUE",AE13="UNRECOGNISED_ADMIN_DISPOSITION"),"Protocol refusal to evaluate",IF(AA13>0,"Stage-A non-admissible - unpatchable for stated claim",IF(AB13>0,"Stage-A non-admissible - patchable",IF(OR(J13="Yes",I13="Indeterminate",AC13>0),"Indeterminate - insufficient evidence",IF(AND(AH13=6,AD13=0),"Stage-A admissible - scoped",IF(AND(AH13+AD13=6,AD13>0),"Stage-A admissible - scoped, control-dependent","Protocol refusal to evaluate")))))))) | S13: =IF(AND(Q13="",R13=""),"",IF(AND(Q13<>"",R13=""),"UNRECORDED",IF(AND(Q13="",R13<>""),"ORPHAN_RECORDED",IF(Q13=R13,"MATCH","MISMATCH")))) | AA13: =COUNTIF(K13:P13,"Material defect - unpatchable for stated claim") | AB13: =COUNTIF(K13:P13,"Material defect - patchable") | AC13: =COUNTIF(K13:P13,"Indeterminate")+COUNTIF(K13:P13,"Not reviewed") | AD13: =COUNTIF(K13:P13,"Adequate - control-dependent") | AE13: =IF(COUNTA(A13:P13)+COUNTA(AJ13)=0,"",IF(AM13<>"OK","UNRECOGNISED_ADMIN_DISPOSITION",IF(AND(AJ13<>"",AJ13<>"None"),IF(OR(LEN(TRIM(A13))=0,LEN(TRIM(B13))=0,LEN(TRIM(C13))=0,LEN(TRIM(F13))=0),"ADMIN_INCOMPLETE","ADMIN_DISPOSITION"),IF(OR(LEN(TRIM(A13))=0,LEN(TRIM(B13))=0,LEN(TRIM(C13))=0,LEN(TRIM(D13))=0,LEN(TRIM(E13))=0,LEN(TRIM(F13))=0,LEN(TRIM(G13))=0,LEN(TRIM(H13))=0,LEN(TRIM(I13))=0,LEN(TRIM(J13))=0,LEN(TRIM(K13))=0,LEN(TRIM(L13))=0,LEN(TRIM(M13))=0,LEN(TRIM(N13))=0,LEN(TRIM(O13))=0,LEN(TRIM(P13))=0),"ADMIN_INCOMPLETE",IF(H13<>"Yes","ADMIN_INVALID",IF(I13="Not feasible","BURDEN_NOT_FEASIBLE",IF(AI13<>"OK","UNRECOGNISED_VALUE","CLEAR"))))))) | AF13: =IF(AND(Q13="",R13=""),"",IF(IF(Q13<>"",Q13,R13)="Stage-A admissible - scoped","stage_a_admissible_scoped",IF(IF(Q13<>"",Q13,R13)="Stage-A admissible - scoped, control-dependent","stage_a_admissible_scoped_control_dependent",IF(IF(Q13<>"",Q13,R13)="Stage-A non-admissible - patchable","stage_a_non_admissible_patchable",IF(IF(Q13<>"",Q13,R13)="Stage-A non-admissible - unpatchable for stated claim","stage_a_non_admissible_unpatchable_for_stated_claim",IF(IF(Q13<>"",Q13,R13)="Indeterminate - insufficient evidence","indeterminate_insufficient_evidence",IF(IF(Q13<>"",Q13,R13)="Protocol refusal to evaluate","protocol_refusal_to_evaluate",IF(IF(Q13<>"",Q13,R13)="Out of scope","out_of_scope",IF(IF(Q13<>"",Q13,R13)="Withdrawn","withdrawn",IF(IF(Q13<>"",Q13,R13)="Not reviewed","not_reviewed","unknown_status")))))))))) | AG13: =IF(AND(AF13="",T13=""),"",IF(AND(AF13<>"",ISNUMBER(SEARCH("token="&AF13&";",T13)),ISNUMBER(SEARCH(AK13,T13)),ISNUMBER(SEARCH("CL basis="&AL13&";",T13))),"VALID","INVALID_OR_INCOMPLETE")) | AH13: =COUNTIF(K13:P13,"Adequate for scope") | AI13: =IF(COUNTA(K13:P13)=0,"",IF(AA13+AB13+AC13+AD13+AH13=6,"OK","UNRECOGNISED_VALUE")) | AK13: =IF(A13="","",Vocabulary!$B$5) | AL13: =IF(A13="","",Vocabulary!$B$6) | AM13: =IF(AJ13="","OK",IF(COUNTIF(Vocabulary!$O$5:$O$8,AJ13)=1,"OK","UNRECOGNISED_ADMIN_DISPOSITION"))
Q14: =IF(AE14="","",IF(AE14="ADMIN_DISPOSITION",AJ14,IF(OR(AE14="ADMIN_INCOMPLETE",AE14="ADMIN_INVALID",AE14="BURDEN_NOT_FEASIBLE",AE14="UNRECOGNISED_VALUE",AE14="UNRECOGNISED_ADMIN_DISPOSITION"),"Protocol refusal to evaluate",IF(AA14>0,"Stage-A non-admissible - unpatchable for stated claim",IF(AB14>0,"Stage-A non-admissible - patchable",IF(OR(J14="Yes",I14="Indeterminate",AC14>0),"Indeterminate - insufficient evidence",IF(AND(AH14=6,AD14=0),"Stage-A admissible - scoped",IF(AND(AH14+AD14=6,AD14>0),"Stage-A admissible - scoped, control-dependent","Protocol refusal to evaluate")))))))) | S14: =IF(AND(Q14="",R14=""),"",IF(AND(Q14<>"",R14=""),"UNRECORDED",IF(AND(Q14="",R14<>""),"ORPHAN_RECORDED",IF(Q14=R14,"MATCH","MISMATCH")))) | AA14: =COUNTIF(K14:P14,"Material defect - unpatchable for stated claim") | AB14: =COUNTIF(K14:P14,"Material defect - patchable") | AC14: =COUNTIF(K14:P14,"Indeterminate")+COUNTIF(K14:P14,"Not reviewed") | AD14: =COUNTIF(K14:P14,"Adequate - control-dependent") | AE14: =IF(COUNTA(A14:P14)+COUNTA(AJ14)=0,"",IF(AM14<>"OK","UNRECOGNISED_ADMIN_DISPOSITION",IF(AND(AJ14<>"",AJ14<>"None"),IF(OR(LEN(TRIM(A14))=0,LEN(TRIM(B14))=0,LEN(TRIM(C14))=0,LEN(TRIM(F14))=0),"ADMIN_INCOMPLETE","ADMIN_DISPOSITION"),IF(OR(LEN(TRIM(A14))=0,LEN(TRIM(B14))=0,LEN(TRIM(C14))=0,LEN(TRIM(D14))=0,LEN(TRIM(E14))=0,LEN(TRIM(F14))=0,LEN(TRIM(G14))=0,LEN(TRIM(H14))=0,LEN(TRIM(I14))=0,LEN(TRIM(J14))=0,LEN(TRIM(K14))=0,LEN(TRIM(L14))=0,LEN(TRIM(M14))=0,LEN(TRIM(N14))=0,LEN(TRIM(O14))=0,LEN(TRIM(P14))=0),"ADMIN_INCOMPLETE",IF(H14<>"Yes","ADMIN_INVALID",IF(I14="Not feasible","BURDEN_NOT_FEASIBLE",IF(AI14<>"OK","UNRECOGNISED_VALUE","CLEAR"))))))) | AF14: =IF(AND(Q14="",R14=""),"",IF(IF(Q14<>"",Q14,R14)="Stage-A admissible - scoped","stage_a_admissible_scoped",IF(IF(Q14<>"",Q14,R14)="Stage-A admissible - scoped, control-dependent","stage_a_admissible_scoped_control_dependent",IF(IF(Q14<>"",Q14,R14)="Stage-A non-admissible - patchable","stage_a_non_admissible_patchable",IF(IF(Q14<>"",Q14,R14)="Stage-A non-admissible - unpatchable for stated claim","stage_a_non_admissible_unpatchable_for_stated_claim",IF(IF(Q14<>"",Q14,R14)="Indeterminate - insufficient evidence","indeterminate_insufficient_evidence",IF(IF(Q14<>"",Q14,R14)="Protocol refusal to evaluate","protocol_refusal_to_evaluate",IF(IF(Q14<>"",Q14,R14)="Out of scope","out_of_scope",IF(IF(Q14<>"",Q14,R14)="Withdrawn","withdrawn",IF(IF(Q14<>"",Q14,R14)="Not reviewed","not_reviewed","unknown_status")))))))))) | AG14: =IF(AND(AF14="",T14=""),"",IF(AND(AF14<>"",ISNUMBER(SEARCH("token="&AF14&";",T14)),ISNUMBER(SEARCH(AK14,T14)),ISNUMBER(SEARCH("CL basis="&AL14&";",T14))),"VALID","INVALID_OR_INCOMPLETE")) | AH14: =COUNTIF(K14:P14,"Adequate for scope") | AI14: =IF(COUNTA(K14:P14)=0,"",IF(AA14+AB14+AC14+AD14+AH14=6,"OK","UNRECOGNISED_VALUE")) | AK14: =IF(A14="","",Vocabulary!$B$5) | AL14: =IF(A14="","",Vocabulary!$B$6) | AM14: =IF(AJ14="","OK",IF(COUNTIF(Vocabulary!$O$5:$O$8,AJ14)=1,"OK","UNRECOGNISED_ADMIN_DISPOSITION"))
